Workbook

Sheet Dashboard
B2: TRUMP TRACKER DASHBOARD
C3: unbiased, raw housing data. Updated every morning at 9:15 EST
B5: Supply | D5: Affordability Score (1-100) | F5: Crash Likelihood (1-100)
B6: ='TRUMP TRACKER'!Q21 -> 46.898679 | D6: ='TRUMP TRACKER'!Q22 -> 45.568 | F6: ='TRUMP TRACKER'!Q23 -> 45.75
B7: ='TRUMP TRACKER'!R21 -> 🟠 Tight Market | D7: ='TRUMP TRACKER'!R22 -> 🟠 Very Strained | F7: ='TRUMP TRACKER'!R23 -> 🟢 Nowhere Close
B8: higher = better | D8: higher = better | F8: higher = closer
D11: Housing Health Score
D12: ='TRUMP TRACKER'!Q28 -> 50.14236
D13: ='TRUMP TRACKER'!R28 -> 🔴 Affordability Crisis
B16: Supply Score Breakdown | C16: We take the current supply of homes and compare it to a | E16: 🟢 Balanced (90–100)
C17: national target. The result is scaled from 0 to 100 | E17: 🟡 Slight Undersupply (70–89.9)
C18: based on how close we are to needed home inventory. | E18: 🟠 Tight Market (45–69.9)
C19: (note: formula favors AFFORDABLE housing in scoring) | E19: 🔴 Critical Shortage (<45)
B23: Affordability Score Breakdown | C23: First-Time Buyer Affordability (max 40 pts) | E23: 🟢 Affordable (80–100)
C24: National Affordability Index (20 pts) | E24: 🟡 Pressured (60–79.9)
C25: Mortgage Rate (15 pts) | E25: 🟠 Strained (40–59.9)
C26: 10-Year Treasury (7.5 pts) | E26: 🔴 Meltdown (<40)
C27: Median Household Income (17.5 pts)
B31: Crash Score Breakdown | C31: We total all macroeconomic pressure points using a fluid | E31: 🔴 MELTDOWN (100–135)
C32: scoring formulas from 15 leading indicators | E32: 🟠 Crash in Sight (80–99.9)
C33: (e.g., delinquencies, vacancies, job market, yield curve). | E33: 🟡 Correction in Sight (70–79.9)
C34: all variables can be seen at A30 on TrumpTracker tab. | E34: 🟢 Buyer’s Market (45–69.9)
E35: 🟢 Strong Seller’s Market (<45)
B39: Housing Health Score Breakdown | E39: 🟢 Affordable Housing (85–100)
C40: 45% if the Affordability score | E40: 🟡 Buyer’s Market (72.5–84.9)
C41: 35% of the Supply score | E41: 🟠 Neutral Market (60–72.4)
C42: 20% of the Inverted Crash score | E42: 🔴 Affordability Crisis (50–59.9)
E43: 🔴 Nowhere Close to Affordable (40–49.9)
E44: 🔥 Crisis Mode (<40)

Sheet TRUMP TRACKER
A1: T.R.U.M.P. Tracker | G1: 21 | I1: HOUSING METRICS | P1: COST TRACKERS | T1: LAST UPDATED: 12/8/2025 01:03 PM EST | U1: LAST UPDATED: 1/7/2026 09:26 AM EST | AC1: =( (K23/J23)*0.5 + (K22/J22)*0.25 + (K24/J24)*0.15 + (K21/J21)*0.1 ) -> 0.51898679
A2: unbiased, raw housing data. Updated DAILY at 9:15 AM Est | I2: KPI | J2: Target | K2: Current | L2: Start | M2: % | N2: Total Change | P2: Builder Expenses | Q2: Current | R2: Start | S2: % | T2: Total Change | W2: Household Expenses pt 2 | X2: Current | Y2: Start | Z2: % | AA2: Total Change
A3: Housing Health Index | I3: Resale Home (Median $) | J3: 385000 | K3: 409200 | L3: 393400 | M3: =(K3 - L3) / L3 -> 0.040162684 | N3: =(K3-L3) -> 15800 | P3: Softwood Lumber | Q3: 252.735 | R3: 267.54 | S3: =(Q3 - R3) / R3 -> -0.05533752 | T3: =IF(OR(Q3="", R3=""), "", Q3 - R3) -> -14.805 | U3: =IF(OR(Q3="", R3="", R3=0), "", IF((Q3 - R3)/R3 >= 0.1, "⬆️⬆️ MAJOR Rise", IF((Q3 - R3)/R3 >= 0.01, "⬆️ Rise", IF((Q3 - R3)/R3 <= -0.1, "⬇️⬇️ MAJOR Drop", IF((Q3 - R3)/R3 <= -0.01, "⬇️ Drop", "Stable"))))) -> ⬇️ Drop | W3: Food Overall | X3: 342.262 | Y3: 335.67 | Z3: =(X3 - Y3) / Y3 -> 0.019638335 | AA3: =IF(OR(X3="", Y3=""), "", X3 - Y3) -> 6.592 | AB3: =IF(OR(X3="", Y3="", Y3=0), "", IF((X3 - Y3)/Y3 >= 0.1, "⬆️⬆️ MAJOR Rise", IF((X3 - Y3)/Y3 >= 0.01, "⬆️ Rise", IF((X3 - Y3)/Y3 <= -0.1, "⬇️⬇️ MAJOR Drop", IF((X3 - Y3)/Y3 <= -0.01, "⬇️ Drop", "Stable"))))) -> ⬆️ Rise
A4: Today | B4: =(Q22 * 0.45) + (Q21 * 0.35) + ((135 - Q23) / 135 * 100) * 0.2 -> 50.14236 | C4: 🔴 Nowhere close to affordable | I4: New Construction (Median $) | J4: 401800 | K4: 413500 | L4: 427900 | M4: =(K4 - L4) / L4 -> -0.033652723 | N4: =(K4-L4) -> -14400 | P4: Steel | Q4: 143.246 | R4: 131.69 | S4: =(Q4 - R4) / R4 -> 0.087751538 | T4: =IF(OR(Q4="", R4=""), "", Q4 - R4) -> 11.556 | U4: =IF(OR(Q4="", R4="", R4=0), "", IF((Q4 - R4)/R4 >= 0.1, "⬆️⬆️ MAJOR Rise", IF((Q4 - R4)/R4 >= 0.01, "⬆️ Rise", IF((Q4 - R4)/R4 <= -0.1, "⬇️⬇️ MAJOR Drop", IF((Q4 - R4)/R4 <= -0.01, "⬇️ Drop", "Stable"))))) -> ⬆️ Rise | W4: Doors/Windows | X4: 473.057 | Y4: 429.67 | Z4: =(X4 - Y4) / Y4 -> 0.10097749 | AA4: =IF(OR(X4="", Y4=""), "", X4 - Y4) -> 43.387 | AB4: =IF(OR(X4="", Y4="", Y4=0), "", IF((X4 - Y4)/Y4 >= 0.1, "⬆️⬆️ MAJOR Rise", IF((X4 - Y4)/Y4 >= 0.01, "⬆️ Rise", IF((X4 - Y4)/Y4 <= -0.1, "⬇️⬇️ MAJOR Drop", IF((X4 - Y4)/Y4 <= -0.01, "⬇️ Drop", "Stable"))))) -> ⬆️⬆️ MAJOR Rise
A5: 90 Day | B5: code in repair | C5: code in repair | I5: Affordable Home (Median $) | J5: 310000 | K5: 362800 | L5: 348600 | M5: =(K5 - L5) / L5 -> 0.040734366 | N5: =(K5-L5) -> 14200 | P5: Shingles | Q5: 369.258 | R5: 359.22 | S5: =(Q5 - R5) / R5 -> 0.027943878 | T5: =IF(OR(Q5="", R5=""), "", Q5 - R5) -> 10.038 | U5: =IF(OR(Q5="", R5="", R5=0), "", IF((Q5 - R5)/R5 >= 0.1, "⬆️⬆️ MAJOR Rise", IF((Q5 - R5)/R5 >= 0.01, "⬆️ Rise", IF((Q5 - R5)/R5 <= -0.1, "⬇️⬇️ MAJOR Drop", IF((Q5 - R5)/R5 <= -0.01, "⬇️ Drop", "Stable"))))) -> ⬆️ Rise | W5: HVAC System | X5: 233.063 | Y5: 222.5 | Z5: =(X5 - Y5) / Y5 -> 0.047474157 | AA5: =IF(OR(X5="", Y5=""), "", X5 - Y5) -> 10.563 | AB5: =IF(OR(X5="", Y5="", Y5=0), "", IF((X5 - Y5)/Y5 >= 0.1, "⬆️⬆️ MAJOR Rise", IF((X5 - Y5)/Y5 >= 0.01, "⬆️ Rise", IF((X5 - Y5)/Y5 <= -0.1, "⬇️⬇️ MAJOR Drop", IF((X5 - Y5)/Y5 <= -0.01, "⬇️ Drop", "Stable"))))) -> ⬆️ Rise
A6: 1 Year | B6: code in repair | C6: code in repair | P6: Plumbing | Q6: 463.869 | R6: 421.34 | S6: =(Q6 - R6) / R6 -> 0.10093749 | T6: =IF(OR(Q6="", R6=""), "", Q6 - R6) -> 42.529 | U6: =IF(OR(Q6="", R6="", R6=0), "", IF((Q6 - R6)/R6 >= 0.1, "⬆️⬆️ MAJOR Rise", IF((Q6 - R6)/R6 >= 0.01, "⬆️ Rise", IF((Q6 - R6)/R6 <= -0.1, "⬇️⬇️ MAJOR Drop", IF((Q6 - R6)/R6 <= -0.01, "⬇️ Drop", "Stable"))))) -> ⬆️⬆️ MAJOR Rise | W6: Fridge | X6: 134.751 | Y6: 132.62 | Z6: =(X6 - Y6) / Y6 -> 0.016068466 | AA6: =IF(OR(X6="", Y6=""), "", X6 - Y6) -> 2.131 | AB6: =IF(OR(X6="", Y6="", Y6=0), "", IF((X6 - Y6)/Y6 >= 0.1, "⬆️⬆️ MAJOR Rise", IF((X6 - Y6)/Y6 >= 0.01, "⬆️ Rise", IF((X6 - Y6)/Y6 <= -0.1, "⬇️⬇️ MAJOR Drop", IF((X6 - Y6)/Y6 <= -0.01, "⬇️ Drop", "Stable"))))) -> ⬆️ Rise
A7: 5 Year | B7: code in repair | C7: code in repair | P7: Concrete | Q7: 252.99 | R7: 251.22 | S7: =(Q7 - R7) / R7 -> 0.0070456174 | T7: =IF(OR(Q7="", R7=""), "", Q7 - R7) -> 1.77 | U7: =IF(OR(Q7="", R7="", R7=0), "", IF((Q7 - R7)/R7 >= 0.1, "⬆️⬆️ MAJOR Rise", IF((Q7 - R7)/R7 >= 0.01, "⬆️ Rise", IF((Q7 - R7)/R7 <= -0.1, "⬇️⬇️ MAJOR Drop", IF((Q7 - R7)/R7 <= -0.01, "⬇️ Drop", "Stable"))))) -> Stable | W7: Water Heater | X7: 641.381 | Y7: 591.49 | Z7: =(X7 - Y7) / Y7 -> 0.084348003 | AA7: =IF(OR(X7="", Y7=""), "", X7 - Y7) -> 49.891 | AB7: =IF(OR(X7="", Y7="", Y7=0), "", IF((X7 - Y7)/Y7 >= 0.1, "⬆️⬆️ MAJOR Rise", IF((X7 - Y7)/Y7 >= 0.01, "⬆️ Rise", IF((X7 - Y7)/Y7 <= -0.1, "⬇️⬇️ MAJOR Drop", IF((X7 - Y7)/Y7 <= -0.01, "⬇️ Drop", "Stable"))))) -> ⬆️ Rise
I8: MORTGAGE | P8: Household Expenses pt 1 | W8: Household Expenses pt 3
A9: Bill Tracker | I9: Mortgage Rate | J9: 0.0672 | K9: 0.0615 | L9: 0.0707 | M9: =(K9 - L9) / L9 -> -0.1301273 | N9: =(K9-L9)*100 -> -0.92 | P9: Power (per KWH) | Q9: 0.189 | R9: 0.179 | S9: =(Q9 - R9) / R9 -> 0.055865922 | T9: =IF(OR(Q9="", R9=""), "", Q9 - R9) -> 0.01 | U9: =IF(OR(Q9="", R9="", R9=0), "", IF((Q9 - R9)/R9 >= 0.1, "⬆️⬆️ MAJOR Rise", IF((Q9 - R9)/R9 >= 0.01, "⬆️ Rise", IF((Q9 - R9)/R9 <= -0.1, "⬇️⬇️ MAJOR Drop", IF((Q9 - R9)/R9 <= -0.01, "⬇️ Drop", "Stable"))))) -> ⬆️ Rise | W9: Beef | X9: 6.54 | Y9: 5.54 | Z9: =(X9 - Y9) / Y9 -> 0.18050542 | AA9: =IF(OR(X9="", Y9=""), "", X9 - Y9) -> 1 | AB9: =IF(OR(X9="", Y9="", Y9=0), "", IF((X9 - Y9)/Y9 >= 0.1, "⬆️⬆️ MAJOR Rise", IF((X9 - Y9)/Y9 >= 0.01, "⬆️ Rise", IF((X9 - Y9)/Y9 <= -0.1, "⬇️⬇️ MAJOR Drop", IF((X9 - Y9)/Y9 <= -0.01, "⬇️ Drop", "Stable"))))) -> ⬆️⬆️ MAJOR Rise
A10: Bill # | B10: Name | C10: Status | I10: Fed Rate | J10: 0.0433 | K10: 0.0372 | L10: 0.0433 | M10: =(K10 - L10) / L10 -> -0.1408776 | N10: =(K10-L10)*100 -> -0.61 | P10: Milk | Q10: 3.997 | R10: 4.03 | S10: =(Q10 - R10) / R10 -> -0.0081885856 | T10: =IF(OR(Q10="", R10=""), "", Q10 - R10) -> -0.033 | U10: =IF(OR(Q10="", R10="", R10=0), "", IF((Q10 - R10)/R10 >= 0.1, "⬆️⬆️ MAJOR Rise", IF((Q10 - R10)/R10 >= 0.01, "⬆️ Rise", IF((Q10 - R10)/R10 <= -0.1, "⬇️⬇️ MAJOR Drop", IF((Q10 - R10)/R10 <= -0.01, "⬇️ Drop", "Stable"))))) -> Stable | W10: Coffee | X10: 9.258 | Y10: 7.01 | Z10: =(X10 - Y10) / Y10 -> 0.32068474 | AA10: =IF(OR(X10="", Y10=""), "", X10 - Y10) -> 2.248 | AB10: =IF(OR(X10="", Y10="", Y10=0), "", IF((X10 - Y10)/Y10 >= 0.1, "⬆️⬆️ MAJOR Rise", IF((X10 - Y10)/Y10 >= 0.01, "⬆️ Rise", IF((X10 - Y10)/Y10 <= -0.1, "⬇️⬇️ MAJOR Drop", IF((X10 - Y10)/Y10 <= -0.01, "⬇️ Drop", "Stable"))))) -> ⬆️⬆️ MAJOR Rise
A11: HR 2945 (US) | B11: Housing for All Act | C11: Currently at committee lvl | I11: 10 Year Treasury Yield | J11: 0.0439 | K11: 0.0417 | L11: 0.04623 | M11: =(K11 - L11) / L11 -> -0.097988319 | N11: =(K11-L11)*100 -> -0.453 | P11: Eggs | Q11: 2.86 | R11: 4.95 | S11: =(Q11 - R11) / R11 -> -0.42222222 | T11: =IF(OR(Q11="", R11=""), "", Q11 - R11) -> -2.09 | U11: =IF(OR(Q11="", R11="", R11=0), "", IF((Q11 - R11)/R11 >= 0.1, "⬆️⬆️ MAJOR Rise", IF((Q11 - R11)/R11 >= 0.01, "⬆️ Rise", IF((Q11 - R11)/R11 <= -0.1, "⬇️⬇️ MAJOR Drop", IF((Q11 - R11)/R11 <= -0.01, "⬇️ Drop", "Stable"))))) -> ⬇️⬇️ MAJOR Drop | W11: Car Parts | X11: 186.065 | Y11: 182.98 | Z11: =(X11 - Y11) / Y11 -> 0.016859766 | AA11: =IF(OR(X11="", Y11=""), "", X11 - Y11) -> 3.085 | AB11: =IF(OR(X11="", Y11="", Y11=0), "", IF((X11 - Y11)/Y11 >= 0.1, "⬆️⬆️ MAJOR Rise", IF((X11 - Y11)/Y11 >= 0.01, "⬆️ Rise", IF((X11 - Y11)/Y11 <= -0.1, "⬇️⬇️ MAJOR Drop", IF((X11 - Y11)/Y11 <= -0.01, "⬇️ Drop", "Stable"))))) -> ⬆️ Rise
A12: HR 2725 (US) | B12: Affordable Housing Credit Improvement | C12: "ways & means" committee | I12: Core Inflation Y.O.Y. | J12: 0.03288774 | K12: 0.02951403 | L12: 0.0363 | M12: =(K12 - L12) / L12 -> -0.18694133 | N12: =(K12-L12)*100 -> -0.67859705 | P12: Bread | Q12: 1.79 | R12: 1.93 | S12: =(Q12 - R12) / R12 -> -0.07253886 | T12: =IF(OR(Q12="", R12=""), "", Q12 - R12) -> -0.14 | U12: =IF(OR(Q12="", R12="", R12=0), "", IF((Q12 - R12)/R12 >= 0.1, "⬆️⬆️ MAJOR Rise", IF((Q12 - R12)/R12 >= 0.01, "⬆️ Rise", IF((Q12 - R12)/R12 <= -0.1, "⬇️⬇️ MAJOR Drop", IF((Q12 - R12)/R12 <= -0.01, "⬇️ Drop", "Stable"))))) -> ⬇️ Drop | W12: Childcare/education | X12: 902.001 | Y12: 879.54 | Z12: =(X12 - Y12) / Y12 -> 0.025537213 | AA12: =IF(OR(X12="", Y12=""), "", X12 - Y12) -> 22.461 | AB12: =IF(OR(X12="", Y12="", Y12=0), "", IF((X12 - Y12)/Y12 >= 0.1, "⬆️⬆️ MAJOR Rise", IF((X12 - Y12)/Y12 >= 0.01, "⬆️ Rise", IF((X12 - Y12)/Y12 <= -0.1, "⬇️⬇️ MAJOR Drop", IF((X12 - Y12)/Y12 <= -0.01, "⬇️ Drop", "Stable"))))) -> ⬆️ Rise
A13: SB 79 (california) | B13: Transit - Orented Housing | C13: Senate Finance Committee | I13: Median Mortgage p/month* | J13: 2250 | K13: 2648.75 | L13: 2705 | M13: =(K13 - L13) / L13 -> -0.020794824 | N13: =(K13-L13) -> -56.25 | P13: Boneless Chicken | Q13: 4.15 | R13: 3.97 | S13: =(Q13 - R13) / R13 -> 0.04534005 | T13: =IF(OR(Q13="", R13=""), "", Q13 - R13) -> 0.18 | U13: =IF(OR(Q13="", R13="", R13=0), "", IF((Q13 - R13)/R13 >= 0.1, "⬆️⬆️ MAJOR Rise", IF((Q13 - R13)/R13 >= 0.01, "⬆️ Rise", IF((Q13 - R13)/R13 <= -0.1, "⬇️⬇️ MAJOR Drop", IF((Q13 - R13)/R13 <= -0.01, "⬇️ Drop", "Stable"))))) -> ⬆️ Rise | W13: Clothing | X13: 132.588 | Y13: 128.175 | Z13: =(X13 - Y13) / Y13 -> 0.034429491 | AA13: =IF(OR(X13="", Y13=""), "", X13 - Y13) -> 4.413 | AB13: =IF(OR(X13="", Y13="", Y13=0), "", IF((X13 - Y13)/Y13 >= 0.1, "⬆️⬆️ MAJOR Rise", IF((X13 - Y13)/Y13 >= 0.01, "⬆️ Rise", IF((X13 - Y13)/Y13 <= -0.1, "⬇️⬇️ MAJOR Drop", IF((X13 - Y13)/Y13 <= -0.01, "⬇️ Drop", "Stable"))))) -> ⬆️ Rise
A14: S 934 (US) | B14: Senate Finance Committee | C14: Senate Finance Committee | I14: AFFORDABILITY | P14: Gallon of Gas | Q14: 3.39 | R14: 3.21 | S14: =(Q14 - R14) / R14 -> 0.056074766 | T14: =IF(OR(Q14="", R14=""), "", Q14 - R14) -> 0.18 | U14: =IF(OR(Q14="", R14="", R14=0), "", IF((Q14 - R14)/R14 >= 0.1, "⬆️⬆️ MAJOR Rise", IF((Q14 - R14)/R14 >= 0.01, "⬆️ Rise", IF((Q14 - R14)/R14 <= -0.1, "⬇️⬇️ MAJOR Drop", IF((Q14 - R14)/R14 <= -0.01, "⬇️ Drop", "Stable"))))) -> ⬆️ Rise | W14: Used Car | X14: 186.488 | Y14: 185.43 | Z14: =(X14 - Y14) / Y14 -> 0.0057056571 | AA14: =IF(OR(X14="", Y14=""), "", X14 - Y14) -> 1.058 | AB14: =IF(OR(X14="", Y14="", Y14=0), "", IF((X14 - Y14)/Y14 >= 0.1, "⬆️⬆️ MAJOR Rise", IF((X14 - Y14)/Y14 >= 0.01, "⬆️ Rise", IF((X14 - Y14)/Y14 <= -0.1, "⬇️⬇️ MAJOR Drop", IF((X14 - Y14)/Y14 <= -0.01, "⬇️ Drop", "Stable"))))) -> Stable
A15: HR {tbd} (US) | B15: No tax on home sales act | C15: recently introduced | I15: FTHB Affordability Index | J15: 95 | K15: 64.6 | L15: 66.8 | M15: =(K15 - L15) / L15 -> -0.032934132 | N15: =(K15-L15)/L15 -> -0.032934132 | P15: Home Insurance | Q15: 266.307 | R15: 260.75 | S15: =(Q15 - R15) / R15 -> 0.021311601 | T15: =IF(OR(Q15="", R15=""), "", Q15 - R15) -> 5.557 | U15: =IF(OR(Q15="", R15="", R15=0), "", IF((Q15 - R15)/R15 >= 0.1, "⬆️⬆️ MAJOR Rise", IF((Q15 - R15)/R15 >= 0.01, "⬆️ Rise", IF((Q15 - R15)/R15 <= -0.1, "⬇️⬇️ MAJOR Drop", IF((Q15 - R15)/R15 <= -0.01, "⬇️ Drop", "Stable"))))) -> ⬆️ Rise | W15: Health Insurance | X15: 163.883 | Y15: 160.488 | Z15: =(X15 - Y15) / Y15 -> 0.02115423 | AA15: =IF(OR(X15="", Y15=""), "", X15 - Y15) -> 3.395 | AB15: =IF(OR(X15="", Y15="", Y15=0), "", IF((X15 - Y15)/Y15 >= 0.1, "⬆️⬆️ MAJOR Rise", IF((X15 - Y15)/Y15 >= 0.01, "⬆️ Rise", IF((X15 - Y15)/Y15 <= -0.1, "⬇️⬇️ MAJOR Drop", IF((X15 - Y15)/Y15 <= -0.01, "⬇️ Drop", "Stable"))))) -> ⬆️ Rise
A16: HR 2710 (US) | B16: People over parking act | C16: recently introduced | I16: Housing Affordability Index | J16: 125 | K16: 106.2 | L16: 100.7 | M16: =(K16 - L16) / L16 -> 0.054617676 | N16: =(K16-L16)/L16 -> 0.054617676 | P16: Car Insurance | Q16: 222.465 | R16: 218.25 | S16: =(Q16 - R16) / R16 -> 0.019312715 | T16: =IF(OR(Q16="", R16=""), "", Q16 - R16) -> 4.215 | U16: =IF(OR(Q16="", R16="", R16=0), "", IF((Q16 - R16)/R16 >= 0.1, "⬆️⬆️ MAJOR Rise", IF((Q16 - R16)/R16 >= 0.01, "⬆️ Rise", IF((Q16 - R16)/R16 <= -0.1, "⬇️⬇️ MAJOR Drop", IF((Q16 - R16)/R16 <= -0.01, "⬇️ Drop", "Stable"))))) -> ⬆️ Rise | W16: Rent | X16: 438.875 | Y16: 429.017 | Z16: =(X16 - Y16) / Y16 -> 0.02297811 | AA16: =IF(OR(X16="", Y16=""), "", X16 - Y16) -> 9.858 | AB16: =IF(OR(X16="", Y16="", Y16=0), "", IF((X16 - Y16)/Y16 >= 0.1, "⬆️⬆️ MAJOR Rise", IF((X16 - Y16)/Y16 >= 0.01, "⬆️ Rise", IF((X16 - Y16)/Y16 <= -0.1, "⬇️⬇️ MAJOR Drop", IF((X16 - Y16)/Y16 <= -0.01, "⬇️ Drop", "Stable"))))) -> ⬆️ Rise
I17: Median Household Income | J17: 80610 | K17: 83730 | L17: 80610 | M17: =(K17 - L17) / L17 -> 0.038704875 | N17: =(K17-L17) -> 3120 | P17: Medical Care | Q17: 585.611 | R17: 571.234 | S17: =(Q17 - R17) / R17 -> 0.02516832 | T17: =IF(OR(Q17="", R17=""), "", Q17 - R17) -> 14.377 | U17: =IF(OR(Q17="", R17="", R17=0), "", IF((Q17 - R17)/R17 >= 0.1, "⬆️⬆️ MAJOR Rise", IF((Q17 - R17)/R17 >= 0.01, "⬆️ Rise", IF((Q17 - R17)/R17 <= -0.1, "⬇️⬇️ MAJOR Drop", IF((Q17 - R17)/R17 <= -0.01, "⬇️ Drop", "Stable"))))) -> ⬆️ Rise | W17: Natural Gas Heat | X17: 1.639 | Y17: 1.552 | Z17: =(X17 - Y17) / Y17 -> 0.056056701 | AA17: =IF(OR(X17="", Y17=""), "", X17 - Y17) -> 0.087 | AB17: =IF(OR(X17="", Y17="", Y17=0), "", IF((X17 - Y17)/Y17 >= 0.1, "⬆️⬆️ MAJOR Rise", IF((X17 - Y17)/Y17 >= 0.01, "⬆️ Rise", IF((X17 - Y17)/Y17 <= -0.1, "⬇️⬇️ MAJOR Drop", IF((X17 - Y17)/Y17 <= -0.01, "⬇️ Drop", "Stable"))))) -> ⬆️ Rise | AC17: =( (K23/J23)*0.5 + (K22/J22)*0.25 + (K24/J24)*0.15 + (K21/J21)*0.1 ) -> 0.51898679
I18: LEGISLATION | W18: Sewer | X18: 321.363 | Y18: 310.23 | Z18: =(X18 - Y18) / Y18 -> 0.035886278 | AA18: =IF(OR(X18="", Y18=""), "", X18 - Y18) -> 11.133 | AB18: =IF(OR(X18="", Y18="", Y18=0), "", IF((X18 - Y18)/Y18 >= 0.1, "⬆️⬆️ MAJOR Rise", IF((X18 - Y18)/Y18 >= 0.01, "⬆️ Rise", IF((X18 - Y18)/Y18 <= -0.1, "⬇️⬇️ MAJOR Drop", IF((X18 - Y18)/Y18 <= -0.01, "⬇️ Drop", "Stable"))))) -> ⬆️ Rise
A19: Affordability by Region | I19: Bills in Congress** | J19: literally anything | K19: 0 | L19: 3 | N19: =2 -> 2 | P19: THE KEY 3 | R19: the 3 scores below, are weighted and used as an index for the Housing Health Score (P27) | W19: Public Transit Fees | X19: 257.461 | Y19: 264.66 | Z19: =(X19 - Y19) / Y19 -> -0.027200937 | AA19: =IF(OR(X19="", Y19=""), "", X19 - Y19) -> -7.199 | AB19: =IF(OR(X19="", Y19="", Y19=0), "", IF((X19 - Y19)/Y19 >= 0.1, "⬆️⬆️ MAJOR Rise", IF((X19 - Y19)/Y19 >= 0.01, "⬆️ Rise", IF((X19 - Y19)/Y19 <= -0.1, "⬇️⬇️ MAJOR Drop", IF((X19 - Y19)/Y19 <= -0.01, "⬇️ Drop", "Stable"))))) -> ⬇️ Drop
A20: metric | B20: North East | C20: Midwest | D20: South | E20: West | I20: SUPPLY | P20: Variable | Q20: Score | R20: Tier | U20: Monthly Change | W20: Furniture | X20: 154.477 | Y20: 148.3 | Z20: =(X20 - Y20) / Y20 -> 0.041652057 | AA20: =IF(OR(X20="", Y20=""), "", X20 - Y20) -> 6.177 | AB20: =IF(OR(X20="", Y20="", Y20=0), "", IF((X20 - Y20)/Y20 >= 0.1, "⬆️⬆️ MAJOR Rise", IF((X20 - Y20)/Y20 >= 0.01, "⬆️ Rise", IF((X20 - Y20)/Y20 <= -0.1, "⬇️⬇️ MAJOR Drop", IF((X20 - Y20)/Y20 <= -0.01, "⬇️ Drop", "Stable"))))) -> ⬆️ Rise
A21: Resale Home (Median $) | B21: 552100 | C21: 333900 | D21: 371300 | E21: 636600 | I21: Total Homes for Sale | J21: 2502500 | K21: 1072417 | L21: 829376 | M21: =(K21 - L21) / L21 -> 0.29304079 | N21: =(K21-L21) -> 243041 | P21: Supply | Q21: =IFS( AC17>=0.9, 100, AC17>=0.8, (AC17 - 0.8)*190 + 80, AC17>=0.65, (AC17 - 0.65)*126.67 + 60, AC17>=0.45, (AC17 - 0.45)*100 + 40, AC17>=0.3, (AC17 - 0.3)*126.67 + 20, TRUE, AC17*30 + 10 ) -> 46.898679 | R21: =IFS( Q21>=90, "🟢 Balanced", Q21>=70, "🟡 Slight Undersupply", Q21>=45, "🟠 Tight Market", TRUE, "🔴 Critical Shortage" ) -> 🟠 Tight Market | U21: TBD | W21: Cleaning supplies | X21: 236.131 | Y21: 223.265 | Z21: =(X21 - Y21) / Y21 -> 0.057626587 | AA21: =IF(OR(X21="", Y21=""), "", X21 - Y21) -> 12.866 | AB21: =IF(OR(X21="", Y21="", Y21=0), "", IF((X21 - Y21)/Y21 >= 0.1, "⬆️⬆️ MAJOR Rise", IF((X21 - Y21)/Y21 >= 0.01, "⬆️ Rise", IF((X21 - Y21)/Y21 <= -0.1, "⬇️⬇️ MAJOR Drop", IF((X21 - Y21)/Y21 <= -0.01, "⬇️ Drop", "Stable"))))) -> ⬆️ Rise
A22: Median Qualifying Income | B22: 136368 | C22: 82464 | D22: 91728 | E22: 157248 | I22: New Construction for Sale | J22: 550000 | K22: 490000 | L22: 496000 | M22: =(K22 - L22) / L22 -> -0.012096774 | N22: =(K22-L22) -> -6000 | P22: Affordability | Q22: =( IFS( K15>=95, 40, K15>=90, 35 + (K15 - 90) * 1, K15>=85, 30 + (K15 - 85) * 1, K15>=80, 25 + (K15 - 80) * 1, K15>=70, 18 + (K15 - 70) * 0.7, K15>=60, 12 + (K15 - 60) * 0.6, TRUE, 6 ) + IFS( K16>=125, 20, K16>=115, 17 + (K16 - 115) * 0.3, K16>=105, 13 + (K16 - 105) * 0.4, K16>=95, 9 + (K16 - 95) * 0.4, K16>=85, 6 + (K16 - 85) * 0.3, TRUE, 3 ) + IFS( K9<=0.045, 15, K9<=0.05, 12 + (0.05 - K9) * 600, K9<=0.055, 9 + (0.055 - K9) * 600, K9<=0.06, 6 + (0.06 - K9) * 600, K9<=0.065, 3 + (0.065 - K9) * 600, K9<=0.07, 1.5 + (0.07 - K9) * 300, TRUE, 0 ) + IFS( K11<=0.023, 7.5, K11<=0.03, 6 + (0.03 - K11) / 0.007 * 1.5, K11<=0.04, 4.5 + (0.04 - K11) / 0.01 * 1.5, K11<=0.045, 3 + (0.045 - K11) / 0.005 * 1.5, K11<=0.05, 1.5 + (0.05 - K11) / 0.005 * 1.5, TRUE, 0 ) + IFS( K17>=100000, 17.5, K17>=97000, 15 + (K17 - 97000) / 3000 * 2.5, K17>=90000, 12 + (K17 - 90000) / 7000 * 3, K17>=85000, 9 + (K17 - 85000) / 5000 * 3, K17>=80000, 6 + (K17 - 80000) / 5000 * 3, TRUE, 3 ) ) -> 45.568 | R22: =IFS( Q22>=80, "🟢 Affordable", Q22>=60, "🟡 Pressured", Q22>=40, "🟠 Very Strained", TRUE, "🔴 Meltdown" ) -> 🟠 Very Strained | U22: TBD | W22: Streaming / Cable TV | X22: 599.226 | Y22: 595.023 | Z22: =(X22 - Y22) / Y22 -> 0.0070635925 | AA22: =IF(OR(X22="", Y22=""), "", X22 - Y22) -> 4.203 | AB22: =IF(OR(X22="", Y22="", Y22=0), "", IF((X22 - Y22)/Y22 >= 0.1, "⬆️⬆️ MAJOR Rise", IF((X22 - Y22)/Y22 >= 0.01, "⬆️ Rise", IF((X22 - Y22)/Y22 <= -0.1, "⬇️⬇️ MAJOR Drop", IF((X22 - Y22)/Y22 <= -0.01, "⬇️ Drop", "Stable"))))) -> Stable
A23: Median Family Income | B23: 115443 | C23: 103209 | D23: 98566 | E23: 114661 | I23: Resale Homes for Sale | J23: 2000500 | K23: =K21-K22 -> 582417 | L23: =L21-L22 -> 333376 | M23: =(K23 - L23) / L23 -> 0.74702738 | N23: =(K23-L23) -> 249041 | P23: Crash Likelihood | Q23: =MIN(100, SUM(E32:E51)) -> 45.75 | R23: =IFS( Q23>=100, "🔴 MELTDOWN", Q23>=80, "🟠 Crash in Sight", Q23>=70, "🟡 Correction in Sight", Q23>=50, "🟡 Starting to Stall", TRUE, "🟢 Nowhere Close" ) -> 🟢 Nowhere Close | U23: TBD | W23: Internet | X23: 67.99 | Y23: 67.76 | Z23: =(X23 - Y23) / Y23 -> 0.0033943329 | AA23: =IF(OR(X23="", Y23=""), "", X23 - Y23) -> 0.23 | AB23: =IF(OR(X23="", Y23="", Y23=0), "", IF((X23 - Y23)/Y23 >= 0.1, "⬆️⬆️ MAJOR Rise", IF((X23 - Y23)/Y23 >= 0.01, "⬆️ Rise", IF((X23 - Y23)/Y23 <= -0.1, "⬇️⬇️ MAJOR Drop", IF((X23 - Y23)/Y23 <= -0.01, "⬇️ Drop", "Stable"))))) -> Stable
A24: Median Mortgage (P&I) | B24: 2841 | C24: 1718 | D24: 1911 | E24: 3276 | I24: Building Permits | J24: 1850000 | K24: 1330000 | L24: 1456000 | M24: =(K24 - L24) / L24 -> -0.086538462 | N24: =(K24-L24) -> -126000 | W24: Food away from home | X24: 387.202 | Y24: 375.53 | Z24: =(X24 - Y24) / Y24 -> 0.031081405 | AA24: =IF(OR(X24="", Y24=""), "", X24 - Y24) -> 11.672 | AB24: =IF(OR(X24="", Y24="", Y24=0), "", IF((X24 - Y24)/Y24 >= 0.1, "⬆️⬆️ MAJOR Rise", IF((X24 - Y24)/Y24 >= 0.01, "⬆️ Rise", IF((X24 - Y24)/Y24 <= -0.1, "⬇️⬇️ MAJOR Drop", IF((X24 - Y24)/Y24 <= -0.01, "⬇️ Drop", "Stable"))))) -> ⬆️ Rise
A25: Affordability today | B25: 92.7 | C25: 131.9 | D25: 109.9 | E25: 75 | I25: *$2,000 in HI & $2,000 in property taxes are escrowed into this payment. 30 year term w/ 10% down. No HOA or PMI. Based off "Resale Home (Median $) | W25: Personal Care | X25: 364.342 | Y25: 351.736 | Z25: =(X25 - Y25) / Y25 -> 0.03583938 | AA25: =IF(OR(X25="", Y25=""), "", X25 - Y25) -> 12.606 | AB25: =IF(OR(X25="", Y25="", Y25=0), "", IF((X25 - Y25)/Y25 >= 0.1, "⬆️⬆️ MAJOR Rise", IF((X25 - Y25)/Y25 >= 0.01, "⬆️ Rise", IF((X25 - Y25)/Y25 <= -0.1, "⬇️⬇️ MAJOR Drop", IF((X25 - Y25)/Y25 <= -0.01, "⬇️ Drop", "Stable"))))) -> ⬆️ Rise
A26: month prior | B26: 84.7 | C26: 125.2 | D26: 107.5 | E26: 72.9 | I26: **tracking for "Regulatory Costs", "Zoning Laws", "Impact Fee Structure", and "First time home buyer" related legislation | W26: Rice per lb | X26: 1.065 | Y26: 1.008 | Z26: =(X26 - Y26) / Y26 -> 0.056547619 | AA26: =IF(OR(X26="", Y26=""), "", X26 - Y26) -> 0.057 | AB26: =IF(OR(X26="", Y26="", Y26=0), "", IF((X26 - Y26)/Y26 >= 0.1, "⬆️⬆️ MAJOR Rise", IF((X26 - Y26)/Y26 >= 0.01, "⬆️ Rise", IF((X26 - Y26)/Y26 <= -0.1, "⬇️⬇️ MAJOR Drop", IF((X26 - Y26)/Y26 <= -0.01, "⬇️ Drop", "Stable"))))) -> ⬆️ Rise
A27: last year | B27: 95.4 | C27: 135.7 | D27: 109.2 | E27: 71 | P27: Housing Health Index | W27: Flour per lb | X27: 0.552 | Y27: 0.56 | Z27: =(X27 - Y27) / Y27 -> -0.014285714 | AA27: =IF(OR(X27="", Y27=""), "", X27 - Y27) -> -0.008 | AB27: =IF(OR(X27="", Y27="", Y27=0), "", IF((X27 - Y27)/Y27 >= 0.1, "⬆️⬆️ MAJOR Rise", IF((X27 - Y27)/Y27 >= 0.01, "⬆️ Rise", IF((X27 - Y27)/Y27 <= -0.1, "⬇️⬇️ MAJOR Drop", IF((X27 - Y27)/Y27 <= -0.01, "⬇️ Drop", "Stable"))))) -> ⬇️ Drop
A28: Yearly Change | B28: =(B25 - B27) / B27 -> -0.028301887 | C28: =(C25 - C27) / C27 -> -0.028002948 | D28: =(D25 - D27) / D27 -> 0.0064102564 | E28: =(E25 - E27) / E27 -> 0.056338028 | I28: Monthly Email Updates | P28: Today | Q28: =(Q22 * 0.45) + (Q21 * 0.35) + ((135 - Q23) / 135 * 100) * 0.2 -> 50.14236 | R28: =IFS( Q28 >= 85, "🟢 Affordable Housing", Q28 >= 72.5, "🟡 Buyer's Market", Q28 >= 60, "🟠 Neutral Market", Q28 >= 50, "🔴 Affordability Crisis", Q28 >= 40, "🔴 Nowhere close to affordable", TRUE, "🔥 Crisis Mode ") -> 🔴 Affordability Crisis | W28: Sugar per lb | X28: 0.991 | Y28: 1.011 | Z28: =(X28 - Y28) / Y28 -> -0.019782394 | AA28: =IF(OR(X28="", Y28=""), "", X28 - Y28) -> -0.02 | AB28: =IF(OR(X28="", Y28="", Y28=0), "", IF((X28 - Y28)/Y28 >= 0.1, "⬆️⬆️ MAJOR Rise", IF((X28 - Y28)/Y28 >= 0.01, "⬆️ Rise", IF((X28 - Y28)/Y28 <= -0.1, "⬇️⬇️ MAJOR Drop", IF((X28 - Y28)/Y28 <= -0.01, "⬇️ Drop", "Stable"))))) -> ⬇️ Drop
I29: links with promises + updates | W29: Tomatoes per lb | X29: 1.828 | Y29: 2.05 | Z29: =(X29 - Y29) / Y29 -> -0.10829268 | AA29: =IF(OR(X29="", Y29=""), "", X29 - Y29) -> -0.222 | AB29: =IF(OR(X29="", Y29="", Y29=0), "", IF((X29 - Y29)/Y29 >= 0.1, "⬆️⬆️ MAJOR Rise", IF((X29 - Y29)/Y29 >= 0.01, "⬆️ Rise", IF((X29 - Y29)/Y29 <= -0.1, "⬇️⬇️ MAJOR Drop", IF((X29 - Y29)/Y29 <= -0.01, "⬇️ Drop", "Stable"))))) -> ⬇️⬇️ MAJOR Drop
A30: HOUSING CRASH TRACKER (P23) | I30: Agenda 47 | P30: Economic Index (under construction) | W30: Bananas per lb | X30: 0.664 | Y30: 0.62 | Z30: =(X30 - Y30) / Y30 -> 0.070967742 | AA30: =IF(OR(X30="", Y30=""), "", X30 - Y30) -> 0.044 | AB30: =IF(OR(X30="", Y30="", Y30=0), "", IF((X30 - Y30)/Y30 >= 0.1, "⬆️⬆️ MAJOR Rise", IF((X30 - Y30)/Y30 >= 0.01, "⬆️ Rise", IF((X30 - Y30)/Y30 <= -0.1, "⬇️⬇️ MAJOR Drop", IF((X30 - Y30)/Y30 <= -0.01, "⬇️ Drop", "Stable"))))) -> ⬆️ Rise
A31: Variable | C31: Category | D31: Current | E31: Points | F31: Tier | I31: Everything Trump has done so far to effect Housing (click) | P31: **We compare each item’s current cost to its 2019 Q1 cost, weight essentials (food, utilities, rent, insurance, medical, etc.) more heavily than discretionary bills, average those ratios, and scale the result so 2019 Q1 equals 100. | W31: Potatoes per lb | X31: 1.014 | Y31: 0.973 | Z31: =(X31 - Y31) / Y31 -> 0.042137718 | AA31: =IF(OR(X31="", Y31=""), "", X31 - Y31) -> 0.041 | AB31: =IF(OR(X31="", Y31="", Y31=0), "", IF((X31 - Y31)/Y31 >= 0.1, "⬆️⬆️ MAJOR Rise", IF((X31 - Y31)/Y31 >= 0.01, "⬆️ Rise", IF((X31 - Y31)/Y31 <= -0.1, "⬇️⬇️ MAJOR Drop", IF((X31 - Y31)/Y31 <= -0.01, "⬇️ Drop", "Stable"))))) -> ⬆️ Rise
A32: Unemployment Rate | C32: Critical | D32: 0.046 | E32: =IFS(D32 < 0.04, 0, D32 < 0.06, 3, D32 < 0.08, 6, D32 < 0.1, 9, TRUE, 12) -> 3 | F32: =IFS( E32>=10, "🔴 High Risk", E32>=6, "🟠 Elevated Risk", E32>=3, "🟡 Moderate Risk", TRUE, "🟢 Low Risk" ) -> 🟡 Moderate Risk | I32: Latest on Housing & Urban Development | P32: Date | Q32: Index** | R32: MoM Change | S32: % | T32: YoY | U32: % | W32: Lettuce per lb | X32: 3.399 | Y32: 2.83 | Z32: =(X32 - Y32) / Y32 -> 0.20106007 | AA32: =IF(OR(X32="", Y32=""), "", X32 - Y32) -> 0.569 | AB32: =IF(OR(X32="", Y32="", Y32=0), "", IF((X32 - Y32)/Y32 >= 0.1, "⬆️⬆️ MAJOR Rise", IF((X32 - Y32)/Y32 >= 0.01, "⬆️ Rise", IF((X32 - Y32)/Y32 <= -0.1, "⬇️⬇️ MAJOR Drop", IF((X32 - Y32)/Y32 <= -0.01, "⬇️ Drop", "Stable"))))) -> ⬆️⬆️ MAJOR Rise
A33: FHA Mortgage Delinquency Rate | C33: Critical | D33: 0.041 | E33: =IFS(D33 < 0.05, 0, D33 < 0.1, 3, D33 < 0.13, 6, D33 < 0.15, 9, TRUE, 12) -> 0 | F33: =IFS( E33>=10, "🔴 High Risk", E33>=6, "🟠 Elevated Risk", E33>=3, "🟡 Moderate Risk", TRUE, "🟢 Low Risk" ) -> 🟢 Low Risk | I33: Project 2025 Tracker (projected housing related changes) | P33: 46021 | Q33: N/a | R33: {=IF(P33:P69="","", IF(Q32:Q68="","", Q33:Q69 - Q32:Q68 ) )} -> #REF! | S33: N/a | W33: Cheddar Cheese per lb | X33: 5.636 | Y33: 5.698 | Z33: =(X33 - Y33) / Y33 -> -0.010881011 | AA33: =IF(OR(X33="", Y33=""), "", X33 - Y33) -> -0.062 | AB33: =IF(OR(X33="", Y33="", Y33=0), "", IF((X33 - Y33)/Y33 >= 0.1, "⬆️⬆️ MAJOR Rise", IF((X33 - Y33)/Y33 >= 0.01, "⬆️ Rise", IF((X33 - Y33)/Y33 <= -0.1, "⬇️⬇️ MAJOR Drop", IF((X33 - Y33)/Y33 <= -0.01, "⬇️ Drop", "Stable"))))) -> ⬇️ Drop
A34: Total Mortgage Delinquency Rate | C34: Critical | D34: 0.0178 | E34: =IFS(D34<2%, 0, D34<5%, 5, D34<10%, 10, TRUE, 15) -> 0 | F34: =IFS( E34>=10, "🔴 High Risk", E34>=6, "🟠 Elevated Risk", E34>=3, "🟡 Moderate Risk", TRUE, "🟢 Low Risk" ) -> 🟢 Low Risk | P34: 45991 | Q34: "insufficient Data due to shutdown" | W34: Bacon per lb | X34: 6.928 | Y34: 7.044 | Z34: =(X34 - Y34) / Y34 -> -0.016467916 | AA34: =IF(OR(X34="", Y34=""), "", X34 - Y34) -> -0.116 | AB34: =IF(OR(X34="", Y34="", Y34=0), "", IF((X34 - Y34)/Y34 >= 0.1, "⬆️⬆️ MAJOR Rise", IF((X34 - Y34)/Y34 >= 0.01, "⬆️ Rise", IF((X34 - Y34)/Y34 <= -0.1, "⬇️⬇️ MAJOR Drop", IF((X34 - Y34)/Y34 <= -0.01, "⬇️ Drop", "Stable"))))) -> ⬇️ Drop
A35: Total Housing Supply | C35: Critical | D35: 1072417 | E35: =IFS(D35 > 0.6, 0, D35 > 0.45, 3, D35 > 0.3, 6, D35 > 0.15, 9, TRUE, 12) -> 0 | F35: =IFS( E35>=10, "🔴 High Risk", E35>=6, "🟠 Elevated Risk", E35>=3, "🟡 Moderate Risk", TRUE, "🟢 Low Risk" ) -> 🟢 Low Risk | I35: INVESTMENT TRACKER | P35: =IFERROR(__xludf.DUMMYFUNCTION("IFERROR( SORT( FILTER( COST_INDEX!$A$7:$A50501, COST_INDEX!$C$7:$C50501<>"""" ), 1, FALSE ), """") "),45961.0) -> 45961 | Q35: {=IF( P35:P44="", "", VLOOKUP(P35:P44, COST_INDEX!$A$7:$C50501, 3, FALSE) )} -> 0 | R35: {=IF(P35:P69="","", IF(Q36:Q70="","", Q35:Q69 - Q36:Q70 ) )} -> -138.19723 | S35: {=IF(P35:P69="","", IF(Q36:Q70="","", Q35:Q69 / Q36:Q70 - 1 ) )} -> -1 | T35: {=IF(P35:P69="","", IFERROR( Q35:Q69 - VLOOKUP( EDATE(P35:P69,-12), {P35:P69, Q35:Q69}, 2, FALSE ), "" ) )} | U35: {=IF(P35:P69="","", IFERROR( Q35:Q69 / VLOOKUP( EDATE(P35:P69,-12), {P35:P69, Q35:Q69}, 2, FALSE ) - 1, "" ) )} | W35: Potato Chips | X35: 6.821 | Y35: 6.474 | Z35: =(X35 - Y35) / Y35 -> 0.053599011 | AA35: =IF(OR(X35="", Y35=""), "", X35 - Y35) -> 0.347 | AB35: =IF(OR(X35="", Y35="", Y35=0), "", IF((X35 - Y35)/Y35 >= 0.1, "⬆️⬆️ MAJOR Rise", IF((X35 - Y35)/Y35 >= 0.01, "⬆️ Rise", IF((X35 - Y35)/Y35 <= -0.1, "⬇️⬇️ MAJOR Drop", IF((X35 - Y35)/Y35 <= -0.01, "⬇️ Drop", "Stable"))))) -> ⬆️ Rise
A36: Disposable Income of Homeowners | C36: Major | D36: 0.11249194 | E36: =IFS(D36 > 0.13, 0, D36 > 0.11, 2, D36 > 0.09, 4, D36 > 0.07, 6, TRUE, 8) -> 2 | F36: =IFS( E36>=10, "🔴 High Risk", E36>=6, "🟠 Elevated Risk", E36>=3, "🟡 Moderate Risk", TRUE, "🟢 Low Risk" ) -> 🟢 Low Risk | P36: =IFERROR(__xludf.DUMMYFUNCTION("""COMPUTED_VALUE"""),45930.0) -> 45930 | Q36: 138.19723 | R36: 0.22109244 | S36: 0.0016023962 | T36: 6.1685316 | U36: 0.046721142 | W36: Disposable Diapers | X36: 106.133 | Y36: 104.949 | Z36: =(X36 - Y36) / Y36 -> 0.01128167 | AA36: =IF(OR(X36="", Y36=""), "", X36 - Y36) -> 1.184 | AB36: =IF(OR(X36="", Y36="", Y36=0), "", IF((X36 - Y36)/Y36 >= 0.1, "⬆️⬆️ MAJOR Rise", IF((X36 - Y36)/Y36 >= 0.01, "⬆️ Rise", IF((X36 - Y36)/Y36 <= -0.1, "⬇️⬇️ MAJOR Drop", IF((X36 - Y36)/Y36 <= -0.01, "⬇️ Drop", "Stable"))))) -> ⬆️ Rise
A37: Foreclosure Rate | C37: Major | D37: 0.006 | E37: =IFS(D37 < 0.005, 0, D37 < 0.01, 2, D37 < 0.02, 4, D37 < 0.03, 6, TRUE, 8) -> 2 | F37: =IFS( E37>=10, "🔴 High Risk", E37>=6, "🟠 Elevated Risk", E37>=3, "🟡 Moderate Risk", TRUE, "🟢 Low Risk" ) -> 🟢 Low Risk | I37: Asset | J37: Value | K37: MoM % | L37: Yoy % | P37: =IFERROR(__xludf.DUMMYFUNCTION("""COMPUTED_VALUE"""),45900.0) -> 45900 | Q37: 137.97614 | R37: 1.0316368 | S37: 0.0075332471 | W37: Oranges per lb | X37: 1.803 | Y37: 1.53 | Z37: =(X37 - Y37) / Y37 -> 0.17843137 | AA37: =IF(OR(X37="", Y37=""), "", X37 - Y37) -> 0.273 | AB37: =IF(OR(X37="", Y37="", Y37=0), "", IF((X37 - Y37)/Y37 >= 0.1, "⬆️⬆️ MAJOR Rise", IF((X37 - Y37)/Y37 >= 0.01, "⬆️ Rise", IF((X37 - Y37)/Y37 <= -0.1, "⬇️⬇️ MAJOR Drop", IF((X37 - Y37)/Y37 <= -0.01, "⬇️ Drop", "Stable"))))) -> ⬆️⬆️ MAJOR Rise
A38: Business Loan Delinquencies | C38: Major | D38: 0.0133 | E38: =IFS(D38 < 0.01, 0, D38 < 0.015, 2, D38 < 0.02, 4, D38 < 0.03, 6, TRUE, 8) -> 2 | F38: =IFS( E38>=10, "🔴 High Risk", E38>=6, "🟠 Elevated Risk", E38>=3, "🟡 Moderate Risk", TRUE, "🟢 Low Risk" ) -> 🟢 Low Risk | I38: Gold | J38: 413.18 | K38: =IFERROR(__xludf.DUMMYFUNCTION("IFERROR( INDEX( INVEST_HISTORY!$A:$O, MAX(FILTER(ROW(INVEST_HISTORY!$A:$A), INVEST_HISTORY!$A:$A<>"""")), MATCH($I38, INVEST_HISTORY!$1:$1, 0) ) / INDEX( INVEST_HISTORY!$A:$O, MAX(FILTER(ROW(INVEST_HISTORY!$A:$A), INVEST_HISTOR"&"Y!$A:$A<>""""))-1, MATCH($I38, INVEST_HISTORY!$1:$1, 0) ) - 1, """") "),0.02592193336508819) -> 0.025921933 | L38: {=IF( J38="", "", IFERROR( J38 / INDEX( INVEST_HISTORY!$B$2:$O$2, 1, MATCH($I38, INVEST_HISTORY!$B$1:$O$1, 0) ) - 1, "" ) )} -> 0.60116257 | P38: =IFERROR(__xludf.DUMMYFUNCTION("""COMPUTED_VALUE"""),45869.0) -> 45869 | Q38: 136.9445 | R38: 0.4612551 | S38: 0.003379573 | W38: Toilet Paper | X38: 150.867 | Y38: 144.932 | Z38: =(X38 - Y38) / Y38 -> 0.040950239 | AA38: =IF(OR(X38="", Y38=""), "", X38 - Y38) -> 5.935 | AB38: =IF(OR(X38="", Y38="", Y38=0), "", IF((X38 - Y38)/Y38 >= 0.1, "⬆️⬆️ MAJOR Rise", IF((X38 - Y38)/Y38 >= 0.01, "⬆️ Rise", IF((X38 - Y38)/Y38 <= -0.1, "⬇️⬇️ MAJOR Drop", IF((X38 - Y38)/Y38 <= -0.01, "⬇️ Drop", "Stable"))))) -> ⬆️ Rise
A39: Delinquency Rate on All Loans | C39: Major | D39: 0.0147 | E39: =IFS(D39 < 0.015, 0, D39 < 0.025, 2, D39 < 0.04, 4, D39 < 0.06, 6, TRUE, 8) -> 0 | F39: =IFS( E39>=10, "🔴 High Risk", E39>=6, "🟠 Elevated Risk", E39>=3, "🟡 Moderate Risk", TRUE, "🟢 Low Risk" ) -> 🟢 Low Risk | I39: Silver | J39: 73.71 | K39: =IFERROR(__xludf.DUMMYFUNCTION("IFERROR( INDEX( INVEST_HISTORY!$A:$O, MAX(FILTER(ROW(INVEST_HISTORY!$A:$A), INVEST_HISTORY!$A:$A<>"""")), MATCH($I39, INVEST_HISTORY!$1:$1, 0) ) / INDEX( INVEST_HISTORY!$A:$O, MAX(FILTER(ROW(INVEST_HISTORY!$A:$A), INVEST_HISTOR"&"Y!$A:$A<>""""))-1, MATCH($I39, INVEST_HISTORY!$1:$1, 0) ) - 1, """") "),0.028703972165845082) -> 0.028703972 | L39: {=IF( J39="", "", IFERROR( J39 / INDEX( INVEST_HISTORY!$B$2:$O$2, 1, MATCH($I39, INVEST_HISTORY!$B$1:$O$1, 0) ) - 1, "" ) )} -> 1.5665042 | P39: =IFERROR(__xludf.DUMMYFUNCTION("""COMPUTED_VALUE"""),45838.0) -> 45838 | Q39: 136.48325 | R39: -0.26013217 | S39: -0.0019023383 | T39: 7.9400959 | U39: 0.061769887 | W39: Trash collection | X39: 204.967 | Y39: 194.665 | Z39: =(X39 - Y39) / Y39 -> 0.052921686 | AA39: =IF(OR(X39="", Y39=""), "", X39 - Y39) -> 10.302 | AB39: =IF(OR(X39="", Y39="", Y39=0), "", IF((X39 - Y39)/Y39 >= 0.1, "⬆️⬆️ MAJOR Rise", IF((X39 - Y39)/Y39 >= 0.01, "⬆️ Rise", IF((X39 - Y39)/Y39 <= -0.1, "⬇️⬇️ MAJOR Drop", IF((X39 - Y39)/Y39 <= -0.01, "⬇️ Drop", "Stable"))))) -> ⬆️ Rise
A40: Credit Card Delinquencies | C40: Minor | D40: 0.0298 | E40: =IFS(D40 < 0.02, 0, D40 < 0.03, 1.5, D40 < 0.04, 3.25, D40 < 0.05, 5, TRUE, 6.25) -> 1.5 | F40: =IFS( E40>=10, "🔴 High Risk", E40>=6, "🟠 Elevated Risk", E40>=3, "🟡 Moderate Risk", TRUE, "🟢 Low Risk" ) -> 🟢 Low Risk | I40: Platinum | J40: 220.45 | K40: =IFERROR(__xludf.DUMMYFUNCTION("IFERROR( INDEX( INVEST_HISTORY!$A:$O, MAX(FILTER(ROW(INVEST_HISTORY!$A:$A), INVEST_HISTORY!$A:$A<>"""")), MATCH($I40, INVEST_HISTORY!$1:$1, 0) ) / INDEX( INVEST_HISTORY!$A:$O, MAX(FILTER(ROW(INVEST_HISTORY!$A:$A), INVEST_HISTOR"&"Y!$A:$A<>""""))-1, MATCH($I40, INVEST_HISTORY!$1:$1, 0) ) - 1, """") "),0.054579326317909294) -> 0.054579326 | L40: {=IF( J40="", "", IFERROR( J40 / INDEX( INVEST_HISTORY!$B$2:$O$2, 1, MATCH($I40, INVEST_HISTORY!$B$1:$O$1, 0) ) - 1, "" ) )} -> 1.4836638 | P40: =IFERROR(__xludf.DUMMYFUNCTION("""COMPUTED_VALUE"""),45808.0) -> 45808 | Q40: 136.74338 | R40: 0.242093 | S40: 0.0017735584 | W40: Cereal | X40: 361.536 | Y40: 356.88 | Z40: =(X40 - Y40) / Y40 -> 0.013046402 | AA40: =IF(OR(X40="", Y40=""), "", X40 - Y40) -> 4.656 | AB40: =IF(OR(X40="", Y40="", Y40=0), "", IF((X40 - Y40)/Y40 >= 0.1, "⬆️⬆️ MAJOR Rise", IF((X40 - Y40)/Y40 >= 0.01, "⬆️ Rise", IF((X40 - Y40)/Y40 <= -0.1, "⬇️⬇️ MAJOR Drop", IF((X40 - Y40)/Y40 <= -0.01, "⬇️ Drop", "Stable"))))) -> ⬆️ Rise
...

Sheet FRED_HISTORY
A1: Date | B1: Median Home Value | C1: Median New Home Sale Price | D1: Mortgage Rate | E1: Fed Funds Rate | F1: 10-Year Treasury Yield | G1: Core Inflation (Sticky) | H1: Housing Affordability Index | I1: Median Household Income | J1: Total Inventory | K1: New Construction Inventory | L1: Building Permits | M1: Unemployment Rate | N1: Mortgage Delinquency | O1: Disposable Income Share | P1: Foreclosure Rate | Q1: Business Loan Delinquency | R1: All Loans Delinquency | S1: Credit Card Delinquency | T1: Rental Vacancy Rate | U1: Job Openings | V1: U6 Unemployment Rate | W1: Temp Help Employment | X1: Lumber | Y1: Steel | Z1: Shingles | AA1: Plumbing | AB1: Concrete | AC1: Power (per KWH) | AD1: Milk | AE1: Eggs | AF1: Bread | AG1: Chicken (boneless) | AH1: Home Insurance | AI1: Auto Insurance | AJ1: Medical Care | AK1: Food Overall | AL1: Doors & Windows | AM1: HVAC System | AN1: Fridge | AO1: Water Heater | AP1: Beef | AQ1: Coffee | AR1: Car Parts | AS1: Childcare / Education | AT1: Clothing | AU1: Used Car | AV1: Health Insurance (PPI) | AW1: Rent | AX1: Natural Gas | AY1: Water/Sewer/Trash (CPI) | AZ1: Public Transit Fares | BA1: Furniture | BB1: Cleaning Supplies | BC1: Cable / Streaming TV | BD1: Internet / IT | BE1: Food Away From Home | BF1: Personal Care | BG1: Rice per lb | BH1: White Flour per lb | BI1: White Sugar per lb | BJ1: Tomatoes per lb | BK1: Bananas per lb | BL1: Potatoes per lb | BM1: Lettuce per lb | BN1: Cheddar Cheese per lb | BO1: Bacon per lb | BP1: Potato Chips | BQ1: Disposable Diapers | BR1: Oranges per lb | BS1: Tissue Paper / Toilet Paper | BT1: Trash Collection (PPI)
A2: 45688 | B2: 393400 | C2: 429600 | D2: 0.0695 | E2: 0.0433 | F2: 0.0458 | G2: 0.036252763 | H2: 101.6 | I2: 80610 | J2: 829376 | K2: 496000 | L2: 1460000 | M2: 0.04 | N2: 0.0178 | O2: 0.11257759 | P2: 0.0047 | Q2: 0.0129 | R2: 0.0156 | S2: 0.0306 | T2: 0.071 | U2: 7762000 | V2: 0.075 | W2: 2543800 | X2: 267.542 | Y2: 131.669 | Z2: 359.216 | AA2: 421.341 | AB2: 251.215 | AC2: 0.179 | AD2: 4.025 | AE2: 4.953 | AF2: 1.925 | AG2: 3.969 | AH2: 261.261 | AI2: 217.268 | AJ2: 571.234 | AK2: 335.671 | AL2: 429.678 | AM2: 222.5 | AN2: 131.262 | AO2: 591.449 | AP2: 5.545 | AQ2: 7.019 | AR2: 182.985 | AS2: 879.514 | AT2: 128.175 | AU2: 185.424 | AV2: 160.448 | AW2: 429.017 | AX2: 1.552 | AY2: 310.239 | AZ2: 264.669 | BA2: 148.308 | BB2: 236.131 | BC2: 595.023 | BD2: 6.766 | BE2: 375.532 | BF2: 351.736 | BG2: 1.008 | BH2: 0.561 | BI2: 1.011 | BJ2: 2.05 | BK2: 0.621 | BL2: 0.973 | BM2: 2.831 | BN2: 5.698 | BO2: 7.044 | BP2: 6.474 | BQ2: 104.949 | BR2: 1.531 | BS2: 144.932 | BT2: 194.665
A3: 45716 | B3: 396800 | C3: 415100 | D3: 0.0676 | E3: 0.0433 | F3: 0.0424 | G3: 0.035165153 | H3: 102.5 | I3: 80610 | J3: 847825 | K3: 499000 | L3: 1454000 | M3: 0.041 | N3: 0.0178 | O3: 0.11257759 | P3: 0.0047 | Q3: 0.0129 | R3: 0.0156 | S3: 0.0306 | T3: 0.071 | U3: 7480000 | V3: 0.08 | W3: 2541600 | X3: 274.907 | Y3: 133.158 | Z3: 356.041 | AA3: 421.341 | AB3: 251.468 | AC3: 0.179 | AD3: 4.026 | AE3: 5.897 | AF3: 1.925 | AG3: 4.079 | AH3: 261.775 | AI3: 218.12 | AJ3: 572.797 | AK3: 336.223 | AL3: 430.286 | AM3: 223.835 | AN3: 130.747 | AO3: 591.449 | AP3: 5.625 | AQ3: 7.246 | AR3: 182.12 | AS3: 881.006 | AT3: 128.862 | AU3: 187.057 | AV3: 160.746 | AW3: 430.224 | AX3: 1.584 | AY3: 313.344 | AZ3: 261.231 | BA3: 149.408 | BB3: 236.131 | BC3: 599.392 | BD3: 6.805 | BE3: 376.991 | BF3: 353.165 | BG3: 1.03 | BH3: 0.561 | BI3: 1.012 | BJ3: 1.848 | BK3: 0.619 | BL3: 0.957 | BM3: 2.865 | BN3: 5.536 | BO3: 6.798 | BP3: 6.462 | BQ3: 104.949 | BR3: 1.536 | BS3: 145.166 | BT3: 196.708
A4: 45747 | B4: 403100 | C4: 412900 | D4: 0.0665 | E4: 0.0433 | F4: 0.0423 | G4: 0.032578151 | H4: 103.5 | I4: 80610 | J4: 892561 | K4: 504000 | L4: 1481000 | M4: 0.042 | N4: 0.0178 | O4: 0.11257759 | P4: 0.0047 | Q4: 0.0129 | R4: 0.0156 | S4: 0.0306 | T4: 0.071 | U4: 7200000 | V4: 0.079 | W4: 2527300 | X4: 287.961 | Y4: 132.455 | Z4: 355.373 | AA4: 421.341 | AB4: 251.42 | AC4: 0.181 | AD4: 4.05 | AE4: 6.227 | AF4: 1.88 | AG4: 4.16 | AH4: 263.589 | AI4: 222.027 | AJ4: 573.966 | AK4: 337.686 | AL4: 434.714 | AM4: 223.791 | AN4: 130.847 | AO4: 591.449 | AP4: 5.79 | AQ4: 7.385 | AR4: 181.89 | AS4: 884.67 | AT4: 126.726 | AU4: 185.772 | AV4: 160.964 | AW4: 431.655 | AX4: 1.596 | AY4: 313.925 | AZ4: 256.412 | BA4: 149.42 | BB4: 236.131 | BC4: 594.03 | BD4: 6.829 | BE4: 378.363 | BF4: 353.554 | BG4: 1.038 | BH4: 0.565 | BI4: 1.014 | BJ4: 1.819 | BK4: 0.625 | BL4: 0.95 | BM4: 2.923 | BN4: 5.737 | BO4: 6.978 | BP4: 6.536 | BQ4: 106.133 | BR4: 1.484 | BS4: 148.794 | BT4: 202.175
A5: 45777 | B5: 414000 | C5: 413600 | D5: 0.0681 | E5: 0.0433 | F5: 0.0417 | G5: 0.031766899 | H5: 100.9 | I5: 80610 | J5: 959251 | K5: 500000 | L5: 1422000 | M5: 0.042 | N5: 0.0178 | O5: 0.11249194 | P5: 0.006 | Q5: 0.0128 | R5: 0.0147 | S5: 0.0304 | T5: 0.07 | U5: 7395000 | V5: 0.078 | W5: 2544200 | X5: 280.407 | Y5: 135.495 | Z5: 352.468 | AA5: 428.847 | AB5: 250.895 | AC5: 0.181 | AD5: 4.074 | AE5: 5.122 | AF5: 1.913 | AG5: 4.18 | AH5: 263.858 | AI5: 221.749 | AJ5: 576.785 | AK5: 337.424 | AL5: 437.606 | AM5: 226.566 | AN5: 130.962 | AO5: 591.449 | AP5: 5.801 | AQ5: 7.536 | AR5: 181.709 | AS5: 885.988 | AT5: 128.994 | AU5: 184.783 | AV5: 161.532 | AW5: 433.13 | AX5: 1.626 | AY5: 314.82 | AZ5: 258.686 | BA5: 150.485 | BB5: 236.131 | BC5: 591.592 | BD5: 6.782 | BE5: 380.039 | BF5: 353.939 | BG5: 1.031 | BH5: 0.557 | BI5: 1.021 | BJ5: 1.793 | BK5: 0.635 | BL5: 0.967 | BM5: 2.915 | BN5: 5.743 | BO5: 7.009 | BP5: 6.611 | BQ5: 106.133 | BR5: 1.485 | BS5: 148.606 | BT5: 201.195
A6: 45808 | B6: 423700 | C6: 424800 | D6: 0.0689 | E6: 0.0433 | F6: 0.0441 | G6: 0.031591311 | H6: 97.1 | I6: 83730 | J6: 1036101 | K6: 504000 | L6: 1394000 | M6: 0.042 | N6: 0.0178 | O6: 0.11249194 | P6: 0.006 | Q6: 0.0128 | R6: 0.0147 | S6: 0.0304 | T6: 0.07 | U6: 7712000 | V6: 0.078 | W6: 2529000 | X6: 271.479 | Y6: 139.919 | Z6: 365.694 | AA6: 438.959 | AB6: 252.303 | AC6: 0.182 | AD6: 4.022 | AE6: 4.548 | AF6: 1.876 | AG6: 4.216 | AH6: 264.252 | AI6: 222.217 | AJ6: 578.236 | AK6: 338.386 | AL6: 437.456 | AM6: 229.204 | AN6: 132.461 | AO6: 641.379 | AP6: 5.981 | AQ6: 7.931 | AR6: 183.402 | AS6: 888.536 | AT6: 131.974 | AU6: 183.779 | AV6: 161.917 | AW6: 434.054 | AX6: 1.626 | AY6: 315.585 | AZ6: 261.734 | BA6: 150.69 | BB6: 236.131 | BC6: 595.208 | BD6: 6.778 | BE6: 381.228 | BF6: 355.642 | BG6: 1.067 | BH6: 0.562 | BI6: 1.054 | BJ6: 1.705 | BK6: 0.655 | BL6: 0.958 | BM6: 2.994 | BN6: 5.908 | BO6: 6.985 | BP6: 6.731 | BQ6: 106.133 | BR6: 1.564 | BS6: 148.885 | BT6: 200.623
A7: 45838 | B7: 432700 | C7: 403600 | D7: 0.0677 | E7: 0.0433 | F7: 0.0424 | G7: 0.03288774 | H7: 95.1 | I7: 83730 | J7: 1082520 | K7: 503000 | L7: 1393000 | M7: 0.041 | N7: 0.0178 | O7: 0.11249194 | P7: 0.006 | Q7: 0.0128 | R7: 0.0147 | S7: 0.0304 | T7: 0.07 | U7: 7357000 | V7: 0.077 | W7: 2519000 | X7: 266.343 | Y7: 144.144 | Z7: 367.402 | AA7: 438.959 | AB7: 252.308 | AC7: 0.19 | AD7: 4.029 | AE7: 3.775 | AF7: 1.864 | AG7: 4.239 | AH7: 264.439 | AI7: 222.183 | AJ7: 580.978 | AK7: 339.498 | AL7: 444.218 | AM7: 231.425 | AN7: 134.217 | AO7: 641.379 | AP7: 6.12 | AQ7: 8.132 | AR7: 184.509 | AS7: 890.277 | AT7: 136.564 | AU7: 182.543 | AV7: 162.375 | AW7: 435.038 | AX7: 1.653 | AY7: 316.851 | AZ7: 258.924 | BA7: 152.394 | BB7: 236.131 | BC7: 597.347 | BD7: 6.797 | BE7: 382.75 | BF7: 357.641 | BG7: 1.061 | BH7: 0.574 | BI7: 1.054 | BJ7: 1.737 | BK7: 0.654 | BL7: 0.981 | BM7: 2.951 | BN7: 5.999 | BO7: 7.098 | BP7: 6.815 | BQ7: 106.133 | BR7: 1.633 | BS7: 148.832 | BT7: 199.748
A8: 45869 | B8: 425700 | C8: 395100 | D8: 0.0672 | E8: 0.0433 | F8: 0.0437 | G8: 0.034198105 | H8: 97.9 | I8: 83730 | J8: 1102787 | K8: 497000 | L8: 1362000 | M8: 0.042 | N8: 0.0178 | O8: 0.11249194 | P8: 0.006 | Q8: 0.0133 | R8: 0.0147 | S8: 0.0298 | T8: 0.07 | U8: 7208000 | V8: 0.079 | W8: 2504000 | X8: 261.368 | Y8: 143.349 | Z8: 367.122 | AA8: 463.869 | AB8: 252.104 | AC8: 0.189 | AD8: 4.162 | AE8: 3.599 | AF8: 1.851 | AG8: 4.204 | AH8: 265.354 | AI8: 222.286 | AJ8: 584.77 | AK8: 339.652 | AL8: 444.383 | AM8: 232.833 | AN8: 135.085 | AO8: 641.381 | AP8: 6.254 | AQ8: 8.414 | AR8: 186.085 | AS8: 893.568 | AT8: 133.021 | AU8: 183.419 | AV8: 163.448 | AW8: 436.152 | AX8: 1.642 | AY8: 318.244 | AZ8: 254.018 | BA8: 152.865 | BB8: 236.131 | BC8: 594.484 | BD8: 6.758 | BE8: 383.808 | BF8: 357.824 | BG8: 1.068 | BH8: 0.557 | BI8: 1.046 | BJ8: 1.793 | BK8: 0.657 | BL8: 0.978 | BM8: 3.006 | BN8: 6.041 | BO8: 7.118 | BP8: 6.797 | BQ8: 106.133 | BR8: 1.77 | BS8: 150.033 | BT8: 202.015
A9: 45900 | B9: 422400 | C9: 413500 | D9: 0.0656 | E9: 0.0433 | F9: 0.0423 | G9: 0.034 | H9: 100.6 | I9: 83730 | J9: 1098681 | K9: 490000 | L9: 1330000 | M9: 0.043 | N9: 0.0178 | O9: 0.11249194 | P9: 0.006 | Q9: 0.0133 | R9: 0.0147 | S9: 0.0298 | T9: 0.07 | U9: 7227000 | V9: 0.081 | W9: 2493900 | X9: 263.714 | Y9: 144.126 | Z9: 369.985 | AA9: 463.869 | AB9: 252.682 | AC9: 0.19 | AD9: 4.171 | AE9: 3.587 | AF9: 1.841 | AG9: 4.212 | AH9: 265.897 | AI9: 222.351 | AJ9: 583.832 | AK9: 341.208 | AL9: 472.839 | AM9: 233.259 | AN9: 133.343 | AO9: 641.381 | AP9: 6.318 | AQ9: 8.872 | AR9: 187.124 | AS9: 895.305 | AT9: 135.835 | AU9: 185.322 | AV9: 163.484 | AW9: 437.462 | AX9: 1.634 | AY9: 319.403 | AZ9: 254.848 | BA9: 153.039 | BB9: 236.131 | BC9: 592.604 | BD9: 6.797 | BE9: 384.909 | BF9: 359.588 | BG9: 1.059 | BH9: 0.557 | BI9: 1.04 | BJ9: 1.925 | BK9: 0.666 | BL9: 1.001 | BM9: 3.006 | BN9: 6.123 | BO9: 7.208 | BP9: 6.751 | BQ9: 106.133 | BR9: 1.795 | BS9: 149.826 | BT9: 202.325
A10: 45930 | B10: 412300 | C10: 413500 | D10: 0.063 | E10: 0.0422 | F10: 0.0416 | G10: 0.033260801 | H10: 104.5 | I10: 83730 | J10: 1100407 | K10: 490000 | L10: 1330000 | M10: 0.044 | N10: 0.0178 | O10: 0.11249194 | P10: 0.006 | Q10: 0.0133 | R10: 0.0147 | S10: 0.0298 | T10: 0.07 | U10: 7227000 | V10: 0.08 | W10: 2478000 | X10: 252.735 | Y10: 143.246 | Z10: 369.258 | AA10: 463.869 | AB10: 252.99 | AC10: 0.188 | AD10: 4.129 | AE10: 3.488 | AF10: 1.867 | AG10: 4.172 | AH10: 266.307 | AI10: 222.465 | AJ10: 585.097 | AK10: 342.054 | AL10: 473.057 | AM10: 233.063 | AN10: 134.751 | AO10: 641.381 | AP10: 6.323 | AQ10: 9.139 | AR10: 188.028 | AS10: 897.302 | AT10: 132.588 | AU10: 184.568 | AV10: 163.883 | AW10: 438.322 | AX10: 1.613 | AY10: 319.867 | AZ10: 259.202 | BA10: 154.023 | BB10: 236.131 | BC10: 593.928 | BD10: 6.772 | BE10: 385.451 | BF10: 362.968 | BG10: 1.06 | BH10: 0.563 | BI10: 1.042 | BJ10: 1.91 | BK10: 0.67 | BL10: 1.014 | BM10: 3.006 | BN10: 6.049 | BO10: 7.29 | BP10: 6.971 | BQ10: 106.133 | BR10: 1.803 | BS10: 150.867 | BT10: 204.967
A11: 45961 | B11: 415200 | D11: 0.0617 | E11: 0.0409 | F11: 0.0411 | J11: 1100001

Sheet FRED_HISTORY_QUARTERLY
A1: Date | B1: Median Home Value | C1: Median New Home Sale Price | D1: Mortgage Rate | E1: Fed Funds Rate | F1: 10-Year Treasury Yield | G1: Core Inflation (Sticky) | H1: Housing Affordability Index | I1: Median Household Income | J1: Total Inventory | K1: New Construction Inventory | L1: Building Permits | M1: Unemployment Rate | N1: Mortgage Delinquency | O1: Disposable Income Share | P1: Foreclosure Rate | Q1: Business Loan Delinquency | R1: All Loans Delinquency | S1: Credit Card Delinquency | T1: Rental Vacancy Rate | U1: Job Openings | V1: U6 Unemployment Rate | W1: Temp Help Employment | X1: Lumber | Y1: Steel | Z1: Shingles | AA1: Plumbing | AB1: Concrete | AC1: Power (per KWH) | AD1: Milk | AE1: Eggs | AF1: Bread | AG1: Chicken (boneless) | AH1: Home Insurance | AI1: Auto Insurance | AJ1: Medical Care | AK1: Food Overall | AL1: Doors & Windows | AM1: HVAC System | AN1: Fridge | AO1: Water Heater | AP1: Beef | AQ1: Coffee | AR1: Car Parts | AS1: Childcare / Education | AT1: Clothing | AU1: Used Car | AV1: Health Insurance (PPI) | AW1: Rent | AX1: Natural Gas | AY1: Water/Sewer/Trash (CPI) | AZ1: Public Transit Fares | BA1: Furniture | BB1: Cleaning Supplies | BC1: Cable / Streaming TV | BD1: Internet / IT | BE1: Food Away From Home | BF1: Personal Care | BG1: Rice per lb | BH1: White Flour per lb | BI1: White Sugar per lb | BJ1: Tomatoes per lb | BK1: Bananas per lb | BL1: Potatoes per lb | BM1: Lettuce per lb | BN1: Cheddar Cheese per lb | BO1: Bacon per lb | BP1: Potato Chips | BQ1: Disposable Diapers | BR1: Oranges per lb | BS1: Tissue Paper / Toilet Paper | BT1: Trash Collection (PPI) | BU1: econ index
A2: 33328 | B2: 100600 | C2: 122500 | D2: 0.0952 | E2: 0.0612 | F2: 0.0805 | G2: 0.054742846 | I2: 63530 | K2: 308000 | L2: 911000 | M2: 0.068 | N2: 0.0309 | O2: 0.11565484 | Q2: 0.0629 | R2: 0.0638 | S2: 0.0526 | T2: 0.075 | W2: 1116100 | X2: 117.2 | Z2: 101.6 | AA2: 170.4 | AC2: 0.085 | AE2: 1.069 | AF2: 0.702 | AJ2: 173.2 | AK2: 135.3 | AL2: 133.6 | AO2: 124.5 | AP2: 1.61 | AQ2: 2.894 | AR2: 101.3 | AS2: 186.2 | AU2: 116.8 | AW2: 142.1 | AX2: 0.599 | AZ2: 153.3 | BA2: 115.7 | BB2: 128.5 | BE2: 136.5 | BF2: 135.8 | BG2: 0.498 | BH2: 0.235 | BI2: 0.434 | BJ2: 0.948 | BK2: 0.577 | BL2: 0.327 | BN2: 3.548 | BO2: 2.318 | BP2: 2.954 | BR2: 0.93
A3: 33419 | B3: 104400 | C3: 119000 | D3: 0.0967 | E3: 0.059 | F3: 0.0824 | G3: 0.049346539 | I3: 63530 | K3: 295000 | L3: 964000 | M3: 0.069 | N3: 0.0318 | O3: 0.11419594 | Q3: 0.0641 | R3: 0.0604 | S3: 0.0548 | T3: 0.073 | W3: 1113700 | X3: 138.2 | Z3: 100.2 | AA3: 170.6 | AC3: 0.09 | AE3: 0.884 | AF3: 0.705 | AJ3: 176.4 | AK3: 137.4 | AL3: 133.3 | AO3: 124.4 | AP3: 1.604 | AQ3: 2.866 | AR3: 101.7 | AS3: 190 | AU3: 118.4 | AW3: 143.2 | AX3: 0.586 | AZ3: 146.6 | BA3: 115.9 | BE3: 137.8 | BF3: 137.3 | BG3: 0.506 | BH3: 0.237 | BI3: 0.432 | BJ3: 1.672 | BK3: 0.532 | BL3: 0.386 | BN3: 3.528 | BO3: 2.305 | BP3: 3.062
A4: 33511 | B4: 102900 | C4: 120000 | D4: 0.0892 | E4: 0.0545 | F4: 0.0747 | G4: 0.044435948 | I4: 63530 | K4: 291000 | L4: 974000 | M4: 0.069 | N4: 0.0323 | O4: 0.11306831 | Q4: 0.0622 | R4: 0.0593 | S4: 0.0535 | T4: 0.076 | W4: 1130500 | X4: 126.1 | Z4: 98.9 | AA4: 171.3 | AC4: 0.091 | AE4: 0.987 | AF4: 0.717 | AJ4: 179.9 | AK4: 136.4 | AL4: 133.3 | AO4: 123.9 | AP4: 1.553 | AQ4: 2.692 | AR4: 102.5 | AS4: 196.5 | AU4: 118.4 | AW4: 144.4 | AX4: 0.589 | AZ4: 146.6 | BA4: 116.4 | BB4: 129.3 | BE4: 138.9 | BF4: 137.8 | BG4: 0.506 | BH4: 0.232 | BI4: 0.422 | BJ4: 0.759 | BK4: 0.432 | BL4: 0.314 | BN4: 3.597 | BO4: 2.16 | BP4: 2.901
A5: 33603 | B5: 103100 | C5: 122000 | D5: 0.0835 | E5: 0.0443 | F5: 0.0671 | G5: 0.043469677 | I5: 63530 | K5: 284000 | L5: 1061000 | M5: 0.073 | N5: 0.0328 | O5: 0.11110772 | Q5: 0.0603 | R5: 0.0582 | S5: 0.0532 | T5: 0.073 | W5: 1139000 | X5: 129.7 | Z5: 97.3 | AA5: 171.9 | AC5: 0.085 | AE5: 1.012 | AF5: 0.717 | AJ5: 183.1 | AK5: 137 | AL5: 133.3 | AO5: 123.9 | AP5: 1.577 | AQ5: 2.625 | AR5: 103.2 | AS5: 199.6 | AU5: 119.1 | AW5: 145.1 | AX5: 0.606 | AZ5: 149.8 | BA5: 116.3 | BE5: 139.6 | BF5: 138 | BG5: 0.51 | BH5: 0.223 | BI5: 0.418 | BJ5: 0.793 | BK5: 0.419 | BL5: 0.283 | BN5: 3.534 | BO5: 1.994 | BP5: 2.954 | BR5: 0.652
A6: 33694 | B6: 105100 | C6: 120000 | D6: 0.0898 | E6: 0.0398 | F6: 0.0754 | G6: 0.039758443 | I6: 63010 | K6: 279000 | L6: 1082000 | M6: 0.074 | N6: 0.0312 | O6: 0.10858007 | Q6: 0.0576 | R6: 0.0577 | S6: 0.0527 | T6: 0.074 | W6: 1170500 | X6: 152.9 | Z6: 96.5 | AA6: 175.4 | AC6: 0.086 | AE6: 0.85 | AF6: 0.747 | AJ6: 186.8 | AK6: 137.6 | AL6: 133.1 | AO6: 128.5 | AP6: 1.545 | AQ6: 2.631 | AR6: 103.4 | AS6: 203.5 | AU6: 118.6 | AW6: 146.5 | AX6: 0.567 | AZ6: 153.5 | BA6: 117.7 | BB6: 129.3 | BC6: 183.3 | BE6: 140.1 | BF6: 139.6 | BG6: 0.515 | BH6: 0.239 | BI6: 0.419 | BJ6: 1.729 | BK6: 0.517 | BL6: 0.28 | BN6: 3.612 | BO6: 1.922 | BP6: 2.943 | BR6: 0.563
A7: 33785 | B7: 107000 | C7: 124500 | D7: 0.0843 | E7: 0.0376 | F7: 0.0714 | G7: 0.038601886 | I7: 63010 | K7: 273000 | L7: 1057000 | M7: 0.078 | N7: 0.0306 | O7: 0.10688985 | Q7: 0.0549 | R7: 0.053 | S7: 0.051 | T7: 0.077 | W7: 1208400 | X7: 148.2 | Z7: 97.1 | AA7: 176.9 | AC7: 0.092 | AE7: 0.801 | AF7: 0.757 | AJ7: 189.6 | AK7: 137.6 | AL7: 133.6 | AO7: 127.9 | AP7: 1.535 | AQ7: 2.625 | AR7: 103.2 | AS7: 207.8 | AU7: 122.5 | AW7: 146.7 | AX7: 0.582 | AZ7: 145.3 | BA7: 118.2 | BC7: 185.9 | BE7: 140.6 | BF7: 139.9 | BG7: 0.52 | BH7: 0.244 | BI7: 0.415 | BJ7: 0.747 | BK7: 0.463 | BL7: 0.294 | BN7: 3.588 | BO7: 1.926 | BP7: 2.906 | BR7: 0.573
A8: 33877 | B8: 105600 | C8: 119500 | D8: 0.0802 | E8: 0.0322 | F8: 0.0637 | G8: 0.033492378 | I8: 63010 | K8: 265000 | L8: 1114000 | M8: 0.076 | N8: 0.0288 | O8: 0.10551259 | Q8: 0.0525 | R8: 0.0516 | S8: 0.0498 | T8: 0.073 | W8: 1231300 | X8: 147.3 | Z8: 97.3 | AA8: 176.1 | AC8: 0.092 | AE8: 0.873 | AF8: 0.756 | AJ8: 192.4 | AK8: 138.9 | AL8: 134.4 | AO8: 127.8 | AP8: 1.521 | AQ8: 2.537 | AR8: 103.2 | AS8: 212.1 | AU8: 126.2 | AW8: 147.1 | AX8: 0.604 | AZ8: 145.6 | BA8: 118.3 | BB8: 129.9 | BC8: 186.7 | BE8: 141.2 | BF8: 140.1 | BG8: 0.542 | BH8: 0.249 | BI8: 0.41 | BJ8: 0.765 | BK8: 0.459 | BL8: 0.33 | BN8: 3.565 | BO8: 1.925 | BP8: 2.856
A9: 33969 | B9: 105600 | C9: 126000 | D9: 0.0814 | E9: 0.0292 | F9: 0.067 | G9: 0.034782626 | I9: 63010 | K9: 265000 | L9: 1176000 | M9: 0.074 | N9: 0.0279 | O9: 0.10467593 | Q9: 0.0476 | R9: 0.0484 | S9: 0.0469 | T9: 0.071 | W9: 1282800 | X9: 159.6 | Z9: 99.4 | AA9: 176.1 | AC9: 0.088 | AE9: 0.928 | AF9: 0.738 | AJ9: 195.3 | AK9: 138.8 | AL9: 134.2 | AO9: 127.8 | AP9: 1.5 | AQ9: 2.364 | AR9: 102.6 | AS9: 216.7 | AU9: 128 | AW9: 148.5 | AX9: 0.623 | AZ9: 158.2 | BA9: 118.2 | BC9: 188.4 | BE9: 141.6 | BF9: 141.3 | BG9: 0.525 | BH9: 0.233 | BI9: 0.406 | BJ9: 1.227 | BK9: 0.404 | BL9: 0.308 | BN9: 3.395 | BO9: 1.863 | BP9: 2.84 | BR9: 0.516
A10: 34059 | B10: 105100 | C10: 125000 | D10: 0.075 | E10: 0.0307 | F10: 0.0603 | G10: 0.033344281 | I10: 62700 | K10: 270000 | L10: 1056000 | M10: 0.07 | N10: 0.0278 | O10: 0.10430733 | Q10: 0.0441 | R10: 0.0469 | S10: 0.046 | T10: 0.078 | W10: 1318800 | X10: 212 | Z10: 98.9 | AA10: 178.1 | AC10: 0.088 | AE10: 0.927 | AF10: 0.742 | AJ10: 198.1 | AK10: 139.6 | AL10: 134.9 | AO10: 130.2 | AP10: 1.562 | AQ10: 2.462 | AR10: 102.1 | AS10: 220.9 | AU10: 126.6 | AW10: 149.1 | AX10: 0.616 | AZ10: 163.5 | BA10: 118.7 | BB10: 130.6 | BC10: 199.4 | BE10: 142.4 | BF10: 142.9 | BG10: 0.525 | BH10: 0.238 | BI10: 0.406 | BJ10: 0.88 | BK10: 0.475 | BL10: 0.327 | BN10: 3.35 | BO10: 1.802 | BP10: 2.839 | BR10: 0.506
A11: 34150 | B11: 111900 | C11: 124500 | D11: 0.0734 | E11: 0.0304 | F11: 0.058 | G11: 0.035693269 | I11: 62700 | K11: 275000 | L11: 1130000 | M11: 0.07 | N11: 0.0267 | O11: 0.10365702 | Q11: 0.0401 | R11: 0.0411 | S11: 0.0446 | T11: 0.076 | W11: 1379500 | X11: 185.8 | Z11: 98.2 | AA11: 179 | AC11: 0.094 | AE11: 0.921 | AF11: 0.752 | AJ11: 201.3 | AK11: 140.6 | AL11: 135.7 | AO11: 135.2 | AP11: 1.562 | AQ11: 2.533 | AR11: 101.5 | AS11: 224.8 | AU11: 134.3 | AW11: 150.4 | AX11: 0.636 | AZ11: 164.5 | BA11: 119.1 | BC11: 198.4 | BE11: 143.2 | BF11: 143.3 | BG11: 0.518 | BH11: 0.238 | BI11: 0.403 | BJ11: 1.278 | BK11: 0.446 | BL11: 0.379 | BN11: 3.331 | BO11: 1.949 | BP11: 2.827 | BR11: 0.549
A12: 34242 | B12: 110500 | C12: 129400 | D12: 0.0695 | E12: 0.0309 | F12: 0.054 | G12: 0.036423837 | I12: 62700 | K12: 287000 | L12: 1251000 | M12: 0.067 | N12: 0.0259 | O12: 0.10417195 | Q12: 0.0361 | R12: 0.0383 | S12: 0.0408 | T12: 0.07 | W12: 1424200 | X12: 185.9 | Z12: 97.7 | AA12: 180.6 | AC12: 0.097 | AE12: 0.89 | AF12: 0.748 | AJ12: 203.6 | AK12: 141.4 | AL12: 136 | AO12: 133.8 | AP12: 1.551 | AQ12: 2.493 | AR12: 101.2 | AS12: 228.5 | AU12: 138.7 | AW12: 151 | AX12: 0.646 | AZ12: 168.4 | BA12: 119.6 | BB12: 130.9 | BC12: 201.8 | BE12: 143.8 | BF12: 145.3 | BG12: 0.494 | BH12: 0.232 | BI12: 0.404 | BJ12: 1.092 | BK12: 0.395 | BL12: 0.341 | BN12: 3.336 | BO12: 1.982 | BP12: 2.895
A13: 34334 | B13: 110800 | C13: 125000 | D13: 0.0713 | E13: 0.0296 | F13: 0.0583 | G13: 0.035484759 | I13: 62700 | K13: 293000 | L13: 1461000 | M13: 0.065 | N13: 0.0244 | O13: 0.10380138 | Q13: 0.0305 | R13: 0.0338 | S13: 0.0391 | T13: 0.069 | W13: 1485100 | X13: 208.8 | Z13: 96.8 | AA13: 180.4 | AC13: 0.09 | AE13: 0.871 | AF13: 0.76 | AJ13: 205.8 | AK13: 142.8 | AL13: 135.9 | AO13: 134.2 | AP13: 1.574 | AQ13: 2.48 | AR13: 101.1 | AS13: 232.2 | AU13: 139.3 | AW13: 151.9 | AX13: 0.662 | AZ13: 176.5 | BA13: 120.3 | BC13: 202.1 | BE13: 144.3 | BF13: 146.1 | BG13: 0.495 | BH13: 0.222 | BI13: 0.398 | BJ13: 1.313 | BK13: 0.414 | BL13: 0.364 | BN13: 3.361 | BO13: 2.018 | BP13: 2.918 | BR13: 0.556
A14: 34424 | B14: 109800 | C14: 132300 | D14: 0.078 | E14: 0.0334 | F14: 0.0677 | G14: 0.035701509 | I14: 63370 | K14: 298000 | L14: 1342000 | M14: 0.065 | N14: 0.0239 | O14: 0.10401077 | Q14: 0.0279 | R14: 0.0329 | S14: 0.036 | T14: 0.075 | V14: 0.115 | W14: 1567200 | X14: 210.2 | Z14: 95.3 | AA14: 181.7 | AC14: 0.089 | AE14: 0.926 | AF14: 0.755 | AJ14: 207.9 | AK14: 142.7 | AL14: 137.4 | AO14: 138.2 | AP14: 1.576 | AQ14: 2.515 | AR14: 101.4 | AS14: 235.8 | AU14: 133.6 | AW14: 153.2 | AX14: 0.666 | AZ14: 178.5 | BA14: 120.6 | BB14: 131.9 | BC14: 199.5 | BE14: 144.8 | BF14: 146.6 | BG14: 0.556 | BH14: 0.226 | BI14: 0.401 | BJ14: 0.914 | BK14: 0.5 | BL14: 0.395 | BN14: 3.409 | BO14: 2.017 | BP14: 2.97 | BR14: 0.52
A15: 34515 | B15: 116600 | C15: 133500 | D15: 0.0846 | E15: 0.0425 | F15: 0.0734 | G15: 0.031947385 | I15: 63370 | K15: 315000 | L15: 1357000 | M15: 0.061 | N15: 0.0226 | O15: 0.10466155 | Q15: 0.024 | R15: 0.028 | S15: 0.0329 | T15: 0.074 | V15: 0.11 | W15: 1627600 | X15: 199.8 | Z15: 96 | AA15: 182.5 | AC15: 0.095 | AE15: 0.841 | AF15: 0.761 | AJ15: 210.5 | AK15: 143.8 | AL15: 139.8 | AO15: 137.3 | AP15: 1.511 | AQ15: 2.598 | AR15: 101.8 | AS15: 239.5 | AU15: 140.9 | AW15: 153.5 | AX15: 0.642 | AZ15: 169.9 | BA15: 121.4 | BC15: 197.8 | BE15: 145.5 | BF15: 148.8 | BG15: 0.555 | BH15: 0.236 | BI15: 0.397 | BJ15: 1.047 | BK15: 0.447 | BL15: 0.39 | BN15: 3.28 | BO15: 1.985 | BP15: 2.968 | BR15: 0.618
A16: 34607 | B16: 113300 | C16: 129700 | D16: 0.0882 | E16: 0.0473 | F16: 0.0762 | G16: 0.032542816 | I16: 63370 | K16: 331000 | L16: 1412000 | M16: 0.059 | N16: 0.0216 | O16: 0.1060019 | Q16: 0.0222 | R16: 0.0263 | S16: 0.0325 | T16: 0.072 | V16: 0.104 | W16: 1681100 | X16: 192.9 | Z16: 96.3 | AA16: 183.6 | AC16: 0.096 | AE16: 0.855 | AF16: 0.776 | AJ16: 213.1 | AK16: 145.3 | AL16: 142.5 | AO16: 138.3 | AP16: 1.463 | AQ16: 4.458 | AR16: 101 | AS16: 242.6 | AU16: 145.4 | AW16: 155 | AX16: 0.639 | AZ16: 171.7 | BA16: 121.4 | BB16: 132.7 | BC16: 194.5 | BE16: 146.2 | BF16: 148.7 | BG16: 0.534 | BH16: 0.237 | BI16: 0.403 | BJ16: 0.958 | BK16: 0.453 | BL16: 0.355 | BN16: 3.39 | BO16: 1.973 | BP16: 2.965
A17: 34699 | B17: 113600 | C17: 135000 | D17: 0.0918 | E17: 0.0545 | F17: 0.0784 | G17: 0.029014466 | I17: 63370 | K17: 336000 | L17: 1396000 | M17: 0.055 | N17: 0.0206 | O17: 0.10713335 | Q17: 0.0218 | R17: 0.0251 | S17: 0.0329 | T17: 0.074 | V17: 0.101 | W17: 1722500 | X17: 188.8 | Z17: 96.5 | AA17: 185.2 | AC17: 0.091 | AE17: 0.873 | AF17: 0.748 | AJ17: 215.9 | AK17: 146.8 | AL17: 145.3 | AO17: 138.3 | AP17: 1.38 | AQ17: 4.382 | AR17: 101.7 | AS17: 246.1 | AU17: 151.5 | AW17: 155.7 | AX17: 0.647 | AZ17: 165.6 | BA17: 120.8 | BC17: 196.7 | BE17: 147.1 | BF17: 149.2 | BG17: 0.534 | BH17: 0.225 | BI17: 0.392 | BJ17: 1.428 | BK17: 0.458 | BL17: 0.335 | BN17: 3.322 | BO17: 1.892 | BP17: 3.012 | BR17: 0.552
A18: 34789 | B18: 110900 | C18: 130000 | D18: 0.0838 | E18: 0.0598 | F18: 0.072 | G18: 0.031674812 | I18: 65380 | K18: 346000 | L18: 1226000 | M18: 0.054 | N18: 0.0208 | O18: 0.10903623 | Q18: 0.0212 | R18: 0.0263 | S18: 0.0348 | T18: 0.074 | V18: 0.099 | W18: 1737100 | X18: 185.4 | Z18: 98.4 | AA18: 188 | AC18: 0.091 | AE18: 0.875 | AF18: 0.775 | AJ18: 218.1 | AK18: 147.1 | AL18: 152.4 | AO18: 146.3 | AP18: 1.392 | AQ18: 4.108 | AR18: 101.9 | AS18: 250.1 | AU18: 154.8 | AW18: 156.6 | AX18: 0.629 | AZ18: 174.5 | BA18: 122.6 | BB18: 135.5 | BC18: 198.3 | BE18: 148.1 | BF18: 150.2 | BG18: 0.511 | BH18: 0.242 | BI18: 0.398 | BJ18: 1.081 | BK18: 0.508 | BL18: 0.348 | BN18: 3.348 | BO18: 1.91 | BP18: 2.975 | BR18: 0.571
A19: 34880 | B19: 119600 | C19: 133700 | D19: 0.0753 | E19: 0.06 | F19: 0.0621 | G19: 0.033322835 | I19: 65380 | K19: 348000 | L19: 1305000 | M19: 0.056 | N19: 0.0211 | O19: 0.11096832 | Q19: 0.021 | R19: 0.0244 | S19: 0.037 | T19: 0.077 | V19: 0.101 | W19: 1716500 | X19: 173.7 | Z19: 102.7 | AA19: 188.3 | AC19: 0.098 | AE19: 0.825 | AF19: 0.781 | AJ19: 219.9 | AK19: 148.3 | AL19: 153.6 | AO19: 146.3 | AP19: 1.333 | AQ19: 4.059 | AR19: 102.3 | AS19: 253 | AU19: 158.3 | AW19: 157.6 | AX19: 0.608 | AZ19: 182.5 | BA19: 122.5 | BC19: 200.1 | BE19: 148.8 | BF19: 151 | BG19: 0.518 | BH19: 0.244 | BI19: 0.395 | BJ19: 1.102 | BK19: 0.49 | BL19: 0.396 | BN19: 3.343 | BO19: 1.896 | BP19: 2.987 | BR19: 0.65
